[23/Mar/2018 08:45:18] "GET / HTTP/1.0" 200 8330
[23/Mar/2018 08:45:19] "GET / HTTP/1.0" 200 8330
[23/Mar/2018 08:45:19] "GET / HTTP/1.0" 200 8330
[23/Mar/2018 08:45:19] "GET / HTTP/1.0" 200 8330
[23/Mar/2018 08:45:19] "GET / HTTP/1.0" 200 8330
[23/Mar/2018 08:45:41] "POST /new_web/zc HTTP/1.0" 200 93
[23/Mar/2018 08:45:54] "POST /new_web/bd_sj HTTP/1.0" 200 82
[23/Mar/2018 08:46:13] "GET / HTTP/1.0" 200 8330
Performing system checks...

System check identified no issues (0 silenced).
March 23, 2018 - 08:45:05
Django version 2.0.3, using settings 'project.settings'
Starting development server at http://10.10.23.14:9999/
Quit the server with CONTROL-C.
Performing system checks...

System check identified no issues (0 silenced).
March 23, 2018 - 08:55:13
Django version 2.0.3, using settings 'project.settings'
Starting development server at http://10.10.23.14:9999/
Quit the server with CONTROL-C.
Unhandled exception in thread started by <function check_errors.<locals>.wrapper at 0x7f8b2036a9d8>
Traceback (most recent call last):
  File "/usr/local/python3/lib/python3.6/site-packages/django/utils/autoreload.py", line 225, in wrapper
    fn(*args, **kwargs)
  File "/usr/local/python3/lib/python3.6/site-packages/django/core/management/commands/runserver.py", line 120, in inner_run
    self.check(display_num_errors=True)
  File "/usr/local/python3/lib/python3.6/site-packages/django/core/management/base.py", line 364, in check
    include_deployment_checks=include_deployment_checks,
  File "/usr/local/python3/lib/python3.6/site-packages/django/core/management/base.py", line 351, in _run_checks
    return checks.run_checks(**kwargs)
  File "/usr/local/python3/lib/python3.6/site-packages/django/core/checks/registry.py", line 73, in run_checks
    new_errors = check(app_configs=app_configs)
  File "/usr/local/python3/lib/python3.6/site-packages/django/core/checks/urls.py", line 13, in check_url_config
    return check_resolver(resolver)
  File "/usr/local/python3/lib/python3.6/site-packages/django/core/checks/urls.py", line 23, in check_resolver
    return check_method()
  File "/usr/local/python3/lib/python3.6/site-packages/django/urls/resolvers.py", line 397, in check
    for pattern in self.url_patterns:
  File "/usr/local/python3/lib/python3.6/site-packages/django/utils/functional.py", line 36, in __get__
    res = instance.__dict__[self.name] = self.func(instance)
  File "/usr/local/python3/lib/python3.6/site-packages/django/urls/resolvers.py", line 536, in url_patterns
    patterns = getattr(self.urlconf_module, "urlpatterns", self.urlconf_module)
  File "/usr/local/python3/lib/python3.6/site-packages/django/utils/functional.py", line 36, in __get__
    res = instance.__dict__[self.name] = self.func(instance)
  File "/usr/local/python3/lib/python3.6/site-packages/django/urls/resolvers.py", line 529, in urlconf_module
    return import_module(self.urlconf_name)
  File "/usr/local/python3/lib/python3.6/importlib/__init__.py", line 126, in import_module
    return _bootstrap._gcd_import(name[level:], package, level)
  File "<frozen importlib._bootstrap>", line 994, in _gcd_import
  File "<frozen importlib._bootstrap>", line 971, in _find_and_load
  File "<frozen importlib._bootstrap>", line 955, in _find_and_load_unlocked
  File "<frozen importlib._bootstrap>", line 665, in _load_unlocked
  File "<frozen importlib._bootstrap_external>", line 678, in exec_module
  File "<frozen importlib._bootstrap>", line 219, in _call_with_frames_removed
  File "/home/lxy/share/django/project/project/urls.py", line 18, in <module>
    from app import views as app_views
  File "/home/lxy/share/django/project/app/views.py", line 5, in <module>
    from common.common import Common
  File "/home/lxy/share/common/common.py", line 247
    key_username = 
                  ^
SyntaxError: invalid syntax
Performing system checks...

Performing system checks...

System check identified no issues (0 silenced).
March 23, 2018 - 08:56:39
Django version 2.0.3, using settings 'project.settings'
Starting development server at http://10.10.23.14:9999/
Quit the server with CONTROL-C.
Performing system checks...

System check identified no issues (0 silenced).
March 23, 2018 - 08:56:47
Django version 2.0.3, using settings 'project.settings'
Starting development server at http://10.10.23.14:9999/
Quit the server with CONTROL-C.
Performing system checks...

System check identified no issues (0 silenced).
March 23, 2018 - 08:56:50
Django version 2.0.3, using settings 'project.settings'
Starting development server at http://10.10.23.14:9999/
Quit the server with CONTROL-C.
Performing system checks...

System check identified no issues (0 silenced).
March 23, 2018 - 08:56:58
Django version 2.0.3, using settings 'project.settings'
Starting development server at http://10.10.23.14:9999/
Quit the server with CONTROL-C.
Unhandled exception in thread started by <function check_errors.<locals>.wrapper at 0x7f1e2354b9d8>
Traceback (most recent call last):
  File "/usr/local/python3/lib/python3.6/site-packages/django/utils/autoreload.py", line 225, in wrapper
    fn(*args, **kwargs)
  File "/usr/local/python3/lib/python3.6/site-packages/django/core/management/commands/runserver.py", line 120, in inner_run
    self.check(display_num_errors=True)
  File "/usr/local/python3/lib/python3.6/site-packages/django/core/management/base.py", line 364, in check
    include_deployment_checks=include_deployment_checks,
  File "/usr/local/python3/lib/python3.6/site-packages/django/core/management/base.py", line 351, in _run_checks
    return checks.run_checks(**kwargs)
  File "/usr/local/python3/lib/python3.6/site-packages/django/core/checks/registry.py", line 73, in run_checks
    new_errors = check(app_configs=app_configs)
  File "/usr/local/python3/lib/python3.6/site-packages/django/core/checks/urls.py", line 13, in check_url_config
    return check_resolver(resolver)
  File "/usr/local/python3/lib/python3.6/site-packages/django/core/checks/urls.py", line 23, in check_resolver
    return check_method()
  File "/usr/local/python3/lib/python3.6/site-packages/django/urls/resolvers.py", line 397, in check
    for pattern in self.url_patterns:
  File "/usr/local/python3/lib/python3.6/site-packages/django/utils/functional.py", line 36, in __get__
    res = instance.__dict__[self.name] = self.func(instance)
  File "/usr/local/python3/lib/python3.6/site-packages/django/urls/resolvers.py", line 536, in url_patterns
    patterns = getattr(self.urlconf_module, "urlpatterns", self.urlconf_module)
  File "/usr/local/python3/lib/python3.6/site-packages/django/utils/functional.py", line 36, in __get__
    res = instance.__dict__[self.name] = self.func(instance)
  File "/usr/local/python3/lib/python3.6/site-packages/django/urls/resolvers.py", line 529, in urlconf_module
    return import_module(self.urlconf_name)
  File "/usr/local/python3/lib/python3.6/importlib/__init__.py", line 126, in import_module
    return _bootstrap._gcd_import(name[level:], package, level)
  File "<frozen importlib._bootstrap>", line 994, in _gcd_import
  File "<frozen importlib._bootstrap>", line 971, in _find_and_load
  File "<frozen importlib._bootstrap>", line 955, in _find_and_load_unlocked
  File "<frozen importlib._bootstrap>", line 665, in _load_unlocked
  File "<frozen importlib._bootstrap_external>", line 678, in exec_module
  File "<frozen importlib._bootstrap>", line 219, in _call_with_frames_removed
  File "/home/lxy/share/django/project/project/urls.py", line 18, in <module>
    from app import views as app_views
  File "/home/lxy/share/django/project/app/views.py", line 5, in <module>
    from common.common import Common
  File "/home/lxy/share/common/common.py", line 132
    @staticmethod
    ^
IndentationError: expected an indented block
Performing system checks...

Unhandled exception in thread started by <function check_errors.<locals>.wrapper at 0x7fa5b0a6a9d8>
Traceback (most recent call last):
  File "/usr/local/python3/lib/python3.6/site-packages/django/utils/autoreload.py", line 225, in wrapper
    fn(*args, **kwargs)
  File "/usr/local/python3/lib/python3.6/site-packages/django/core/management/commands/runserver.py", line 120, in inner_run
    self.check(display_num_errors=True)
  File "/usr/local/python3/lib/python3.6/site-packages/django/core/management/base.py", line 364, in check
    include_deployment_checks=include_deployment_checks,
  File "/usr/local/python3/lib/python3.6/site-packages/django/core/management/base.py", line 351, in _run_checks
    return checks.run_checks(**kwargs)
  File "/usr/local/python3/lib/python3.6/site-packages/django/core/checks/registry.py", line 73, in run_checks
    new_errors = check(app_configs=app_configs)
  File "/usr/local/python3/lib/python3.6/site-packages/django/core/checks/urls.py", line 13, in check_url_config
    return check_resolver(resolver)
  File "/usr/local/python3/lib/python3.6/site-packages/django/core/checks/urls.py", line 23, in check_resolver
    return check_method()
  File "/usr/local/python3/lib/python3.6/site-packages/django/urls/resolvers.py", line 397, in check
    for pattern in self.url_patterns:
  File "/usr/local/python3/lib/python3.6/site-packages/django/utils/functional.py", line 36, in __get__
    res = instance.__dict__[self.name] = self.func(instance)
  File "/usr/local/python3/lib/python3.6/site-packages/django/urls/resolvers.py", line 536, in url_patterns
    patterns = getattr(self.urlconf_module, "urlpatterns", self.urlconf_module)
  File "/usr/local/python3/lib/python3.6/site-packages/django/utils/functional.py", line 36, in __get__
    res = instance.__dict__[self.name] = self.func(instance)
  File "/usr/local/python3/lib/python3.6/site-packages/django/urls/resolvers.py", line 529, in urlconf_module
    return import_module(self.urlconf_name)
  File "/usr/local/python3/lib/python3.6/importlib/__init__.py", line 126, in import_module
    return _bootstrap._gcd_import(name[level:], package, level)
  File "<frozen importlib._bootstrap>", line 994, in _gcd_import
  File "<frozen importlib._bootstrap>", line 971, in _find_and_load
  File "<frozen importlib._bootstrap>", line 955, in _find_and_load_unlocked
  File "<frozen importlib._bootstrap>", line 665, in _load_unlocked
  File "<frozen importlib._bootstrap_external>", line 678, in exec_module
  File "<frozen importlib._bootstrap>", line 219, in _call_with_frames_removed
  File "/home/lxy/share/django/project/project/urls.py", line 18, in <module>
    from app import views as app_views
  File "/home/lxy/share/django/project/app/views.py", line 5, in <module>
    from common.common import Common
  File "/home/lxy/share/common/common.py", line 132
    @staticmethod
    ^
IndentationError: expected an indented block
Performing system checks...

Performing system checks...

System check identified no issues (0 silenced).
March 23, 2018 - 08:58:30
Django version 2.0.3, using settings 'project.settings'
Starting development server at http://10.10.23.14:9999/
Quit the server with CONTROL-C.
Performing system checks...

System check identified no issues (0 silenced).
March 23, 2018 - 08:58:37
Django version 2.0.3, using settings 'project.settings'
Starting development server at http://10.10.23.14:9999/
Quit the server with CONTROL-C.
Performing system checks...

System check identified no issues (0 silenced).
March 23, 2018 - 08:58:53
Django version 2.0.3, using settings 'project.settings'
Starting development server at http://10.10.23.14:9999/
Quit the server with CONTROL-C.
Performing system checks...

System check identified no issues (0 silenced).
March 23, 2018 - 08:59:27
Django version 2.0.3, using settings 'project.settings'
Starting development server at http://10.10.23.14:9999/
Quit the server with CONTROL-C.
Performing system checks...

System check identified no issues (0 silenced).
March 23, 2018 - 08:59:48
Django version 2.0.3, using settings 'project.settings'
Starting development server at http://10.10.23.14:9999/
Quit the server with CONTROL-C.
Performing system checks...

System check identified no issues (0 silenced).
March 23, 2018 - 09:00:52
Django version 2.0.3, using settings 'project.settings'
Starting development server at http://10.10.23.14:9999/
Quit the server with CONTROL-C.
Performing system checks...

System check identified no issues (0 silenced).
March 23, 2018 - 09:00:58
Django version 2.0.3, using settings 'project.settings'
Starting development server at http://10.10.23.14:9999/
Quit the server with CONTROL-C.
Performing system checks...

System check identified no issues (0 silenced).
March 23, 2018 - 09:01:06
Django version 2.0.3, using settings 'project.settings'
Starting development server at http://10.10.23.14:9999/
Quit the server with CONTROL-C.
Performing system checks...

System check identified no issues (0 silenced).
March 23, 2018 - 09:01:09
Django version 2.0.3, using settings 'project.settings'
Starting development server at http://10.10.23.14:9999/
Quit the server with CONTROL-C.
Performing system checks...

System check identified no issues (0 silenced).
March 23, 2018 - 09:01:24
Django version 2.0.3, using settings 'project.settings'
Starting development server at http://10.10.23.14:9999/
Quit the server with CONTROL-C.
Unhandled exception in thread started by <function check_errors.<locals>.wrapper at 0x7fe0baf149d8>
Traceback (most recent call last):
  File "/usr/local/python3/lib/python3.6/site-packages/django/utils/autoreload.py", line 225, in wrapper
    fn(*args, **kwargs)
  File "/usr/local/python3/lib/python3.6/site-packages/django/core/management/commands/runserver.py", line 120, in inner_run
    self.check(display_num_errors=True)
  File "/usr/local/python3/lib/python3.6/site-packages/django/core/management/base.py", line 364, in check
    include_deployment_checks=include_deployment_checks,
  File "/usr/local/python3/lib/python3.6/site-packages/django/core/management/base.py", line 351, in _run_checks
    return checks.run_checks(**kwargs)
  File "/usr/local/python3/lib/python3.6/site-packages/django/core/checks/registry.py", line 73, in run_checks
    new_errors = check(app_configs=app_configs)
  File "/usr/local/python3/lib/python3.6/site-packages/django/core/checks/urls.py", line 13, in check_url_config
    return check_resolver(resolver)
  File "/usr/local/python3/lib/python3.6/site-packages/django/core/checks/urls.py", line 23, in check_resolver
    return check_method()
  File "/usr/local/python3/lib/python3.6/site-packages/django/urls/resolvers.py", line 397, in check
    for pattern in self.url_patterns:
  File "/usr/local/python3/lib/python3.6/site-packages/django/utils/functional.py", line 36, in __get__
    res = instance.__dict__[self.name] = self.func(instance)
  File "/usr/local/python3/lib/python3.6/site-packages/django/urls/resolvers.py", line 536, in url_patterns
    patterns = getattr(self.urlconf_module, "urlpatterns", self.urlconf_module)
  File "/usr/local/python3/lib/python3.6/site-packages/django/utils/functional.py", line 36, in __get__
    res = instance.__dict__[self.name] = self.func(instance)
  File "/usr/local/python3/lib/python3.6/site-packages/django/urls/resolvers.py", line 529, in urlconf_module
    return import_module(self.urlconf_name)
  File "/usr/local/python3/lib/python3.6/importlib/__init__.py", line 126, in import_module
    return _bootstrap._gcd_import(name[level:], package, level)
  File "<frozen importlib._bootstrap>", line 994, in _gcd_import
  File "<frozen importlib._bootstrap>", line 971, in _find_and_load
  File "<frozen importlib._bootstrap>", line 955, in _find_and_load_unlocked
  File "<frozen importlib._bootstrap>", line 665, in _load_unlocked
  File "<frozen importlib._bootstrap_external>", line 678, in exec_module
  File "<frozen importlib._bootstrap>", line 219, in _call_with_frames_removed
  File "/home/lxy/share/django/project/project/urls.py", line 18, in <module>
    from app import views as app_views
  File "/home/lxy/share/django/project/app/views.py", line 5, in <module>
    from common.common import Common
  File "/home/lxy/share/common/common.py", line 253
    key_username = 'hm_user_name_redis_prefix:{}'.format(Common.md5()username)
                                                                            ^
SyntaxError: invalid syntax
Performing system checks...

Performing system checks...

System check identified no issues (0 silenced).
March 23, 2018 - 09:02:14
Django version 2.0.3, using settings 'project.settings'
Starting development server at http://10.10.23.14:9999/
Quit the server with CONTROL-C.
[23/Mar/2018 09:03:07] "GET / HTTP/1.0" 200 8330
Performing system checks...

System check identified no issues (0 silenced).
March 23, 2018 - 09:02:41
Django version 2.0.3, using settings 'project.settings'
Starting development server at http://10.10.23.14:9999/
Quit the server with CONTROL-C.
Performing system checks...

System check identified no issues (0 silenced).
March 23, 2018 - 09:04:49
Django version 2.0.3, using settings 'project.settings'
Starting development server at http://10.10.23.14:9999/
Quit the server with CONTROL-C.
Performing system checks...

System check identified no issues (0 silenced).
March 23, 2018 - 09:05:54
Django version 2.0.3, using settings 'project.settings'
Starting development server at http://10.10.23.14:9999/
Quit the server with CONTROL-C.
Performing system checks...

System check identified no issues (0 silenced).
March 23, 2018 - 09:06:03
Django version 2.0.3, using settings 'project.settings'
Starting development server at http://10.10.23.14:9999/
Quit the server with CONTROL-C.
Performing system checks...

System check identified no issues (0 silenced).
March 23, 2018 - 09:06:12
Django version 2.0.3, using settings 'project.settings'
Starting development server at http://10.10.23.14:9999/
Quit the server with CONTROL-C.
Performing system checks...

System check identified no issues (0 silenced).
March 23, 2018 - 09:06:25
Django version 2.0.3, using settings 'project.settings'
Starting development server at http://10.10.23.14:9999/
Quit the server with CONTROL-C.
Performing system checks...

System check identified no issues (0 silenced).
March 23, 2018 - 09:06:36
Django version 2.0.3, using settings 'project.settings'
Starting development server at http://10.10.23.14:9999/
Quit the server with CONTROL-C.
Unhandled exception in thread started by <function check_errors.<locals>.wrapper at 0x7f084e4f09d8>
Traceback (most recent call last):
  File "/usr/local/python3/lib/python3.6/site-packages/django/utils/autoreload.py", line 225, in wrapper
    fn(*args, **kwargs)
  File "/usr/local/python3/lib/python3.6/site-packages/django/core/management/commands/runserver.py", line 120, in inner_run
    self.check(display_num_errors=True)
  File "/usr/local/python3/lib/python3.6/site-packages/django/core/management/base.py", line 364, in check
    include_deployment_checks=include_deployment_checks,
  File "/usr/local/python3/lib/python3.6/site-packages/django/core/management/base.py", line 351, in _run_checks
    return checks.run_checks(**kwargs)
  File "/usr/local/python3/lib/python3.6/site-packages/django/core/checks/registry.py", line 73, in run_checks
    new_errors = check(app_configs=app_configs)
  File "/usr/local/python3/lib/python3.6/site-packages/django/core/checks/urls.py", line 13, in check_url_config
    return check_resolver(resolver)
  File "/usr/local/python3/lib/python3.6/site-packages/django/core/checks/urls.py", line 23, in check_resolver
    return check_method()
  File "/usr/local/python3/lib/python3.6/site-packages/django/urls/resolvers.py", line 397, in check
    for pattern in self.url_patterns:
  File "/usr/local/python3/lib/python3.6/site-packages/django/utils/functional.py", line 36, in __get__
    res = instance.__dict__[self.name] = self.func(instance)
  File "/usr/local/python3/lib/python3.6/site-packages/django/urls/resolvers.py", line 536, in url_patterns
    patterns = getattr(self.urlconf_module, "urlpatterns", self.urlconf_module)
  File "/usr/local/python3/lib/python3.6/site-packages/django/utils/functional.py", line 36, in __get__
    res = instance.__dict__[self.name] = self.func(instance)
  File "/usr/local/python3/lib/python3.6/site-packages/django/urls/resolvers.py", line 529, in urlconf_module
    return import_module(self.urlconf_name)
  File "/usr/local/python3/lib/python3.6/importlib/__init__.py", line 126, in import_module
    return _bootstrap._gcd_import(name[level:], package, level)
  File "<frozen importlib._bootstrap>", line 994, in _gcd_import
  File "<frozen importlib._bootstrap>", line 971, in _find_and_load
  File "<frozen importlib._bootstrap>", line 955, in _find_and_load_unlocked
  File "<frozen importlib._bootstrap>", line 665, in _load_unlocked
  File "<frozen importlib._bootstrap_external>", line 678, in exec_module
  File "<frozen importlib._bootstrap>", line 219, in _call_with_frames_removed
  File "/home/lxy/share/django/project/project/urls.py", line 18, in <module>
    from app import views as app_views
  File "/home/lxy/share/django/project/app/views.py", line 5, in <module>
    from common.common import Common
  File "/home/lxy/share/common/common.py", line 256
    print(ret)
        ^
IndentationError: expected an indented block
Performing system checks...

Performing system checks...

System check identified no issues (0 silenced).
March 23, 2018 - 09:07:04
Django version 2.0.3, using settings 'project.settings'
Starting development server at http://10.10.23.14:9999/
Quit the server with CONTROL-C.
Performing system checks...

System check identified no issues (0 silenced).
March 23, 2018 - 09:07:54
Django version 2.0.3, using settings 'project.settings'
Starting development server at http://10.10.23.14:9999/
Quit the server with CONTROL-C.
Performing system checks...

System check identified no issues (0 silenced).
March 23, 2018 - 09:08:03
Django version 2.0.3, using settings 'project.settings'
Starting development server at http://10.10.23.14:9999/
Quit the server with CONTROL-C.
Unhandled exception in thread started by <function check_errors.<locals>.wrapper at 0x7f9075edd9d8>
Traceback (most recent call last):
  File "/usr/local/python3/lib/python3.6/site-packages/django/utils/autoreload.py", line 225, in wrapper
    fn(*args, **kwargs)
  File "/usr/local/python3/lib/python3.6/site-packages/django/core/management/commands/runserver.py", line 120, in inner_run
    self.check(display_num_errors=True)
  File "/usr/local/python3/lib/python3.6/site-packages/django/core/management/base.py", line 364, in check
    include_deployment_checks=include_deployment_checks,
  File "/usr/local/python3/lib/python3.6/site-packages/django/core/management/base.py", line 351, in _run_checks
    return checks.run_checks(**kwargs)
  File "/usr/local/python3/lib/python3.6/site-packages/django/core/checks/registry.py", line 73, in run_checks
    new_errors = check(app_configs=app_configs)
  File "/usr/local/python3/lib/python3.6/site-packages/django/core/checks/urls.py", line 13, in check_url_config
    return check_resolver(resolver)
  File "/usr/local/python3/lib/python3.6/site-packages/django/core/checks/urls.py", line 23, in check_resolver
    return check_method()
  File "/usr/local/python3/lib/python3.6/site-packages/django/urls/resolvers.py", line 397, in check
    for pattern in self.url_patterns:
  File "/usr/local/python3/lib/python3.6/site-packages/django/utils/functional.py", line 36, in __get__
    res = instance.__dict__[self.name] = self.func(instance)
  File "/usr/local/python3/lib/python3.6/site-packages/django/urls/resolvers.py", line 536, in url_patterns
    patterns = getattr(self.urlconf_module, "urlpatterns", self.urlconf_module)
  File "/usr/local/python3/lib/python3.6/site-packages/django/utils/functional.py", line 36, in __get__
    res = instance.__dict__[self.name] = self.func(instance)
  File "/usr/local/python3/lib/python3.6/site-packages/django/urls/resolvers.py", line 529, in urlconf_module
    return import_module(self.urlconf_name)
  File "/usr/local/python3/lib/python3.6/importlib/__init__.py", line 126, in import_module
    return _bootstrap._gcd_import(name[level:], package, level)
  File "<frozen importlib._bootstrap>", line 994, in _gcd_import
  File "<frozen importlib._bootstrap>", line 971, in _find_and_load
  File "<frozen importlib._bootstrap>", line 955, in _find_and_load_unlocked
  File "<frozen importlib._bootstrap>", line 665, in _load_unlocked
  File "<frozen importlib._bootstrap_external>", line 678, in exec_module
  File "<frozen importlib._bootstrap>", line 219, in _call_with_frames_removed
  File "/home/lxy/share/django/project/project/urls.py", line 18, in <module>
    from app import views as app_views
  File "/home/lxy/share/django/project/app/views.py", line 5, in <module>
    from common.common import Common
  File "/home/lxy/share/common/common.py", line 255
    if not Common.REDIS_INST.get(key_username) and UserName.:
                                                            ^
SyntaxError: invalid syntax
Performing system checks...

Performing system checks...

System check identified no issues (0 silenced).
March 23, 2018 - 09:09:10
Django version 2.0.3, using settings 'project.settings'
Starting development server at http://10.10.23.14:9999/
Quit the server with CONTROL-C.
Performing system checks...

System check identified no issues (0 silenced).
March 23, 2018 - 09:09:48
Django version 2.0.3, using settings 'project.settings'
Starting development server at http://10.10.23.14:9999/
Quit the server with CONTROL-C.
[23/Mar/2018 09:19:30] "GET / HTTP/1.0" 200 8330
[23/Mar/2018 09:19:30] "GET /static/js/jquery-1.10.2.min.js HTTP/1.0" 200 93107
[23/Mar/2018 09:19:30] "GET /static/js/bootstrap.min.js HTTP/1.0" 200 29110
[23/Mar/2018 09:19:30] "GET /static/css/bootstrap.css HTTP/1.0" 200 121220
[23/Mar/2018 09:19:30] "GET /static/js/lucky.js HTTP/1.0" 200 1789
Not Found: /favicon.ico
[23/Mar/2018 09:19:30] "GET /favicon.ico HTTP/1.0" 404 2543
[23/Mar/2018 09:20:15] "GET /static/css/bootstrap.css.map HTTP/1.0" 404 1701
Not Found: /favicon.ico
[23/Mar/2018 09:47:10] "GET /favicon.ico HTTP/1.0" 404 2543
Not Found: /favicon.ico
[23/Mar/2018 09:47:10] "GET /favicon.ico HTTP/1.0" 404 2543
Not Found: /favicon.ico
[23/Mar/2018 09:47:10] "GET /favicon.ico HTTP/1.0" 404 2543
Not Found: /favicon.ico
[23/Mar/2018 09:47:10] "GET /favicon.ico HTTP/1.0" 404 2543
Not Found: /favicon.ico
[23/Mar/2018 09:47:10] "GET /favicon.ico HTTP/1.0" 404 2543
Not Found: /favicon.ico
[23/Mar/2018 09:47:10] "GET /favicon.ico HTTP/1.0" 404 2543
Not Found: /favicon.ico
[23/Mar/2018 09:47:10] "GET /favicon.ico HTTP/1.0" 404 2543
Not Found: /favicon.ico
[23/Mar/2018 09:47:10] "GET /favicon.ico HTTP/1.0" 404 2543
Not Found: /favicon.ico
[23/Mar/2018 09:51:27] "GET /favicon.ico HTTP/1.0" 404 2543
Not Found: /favicon.ico
[23/Mar/2018 09:51:27] "GET /favicon.ico HTTP/1.0" 404 2543
Not Found: /favicon.ico
[23/Mar/2018 09:51:27] "GET /favicon.ico HTTP/1.0" 404 2543
Not Found: /favicon.ico
[23/Mar/2018 09:51:27] "GET /favicon.ico HTTP/1.0" 404 2543
Not Found: /favicon.ico
[23/Mar/2018 10:29:52] "GET /favicon.ico HTTP/1.0" 404 2543
[23/Mar/2018 11:41:52] "GET / HTTP/1.0" 200 8330
[23/Mar/2018 11:41:52] "GET /static/js/lucky.js HTTP/1.0" 200 1789
[23/Mar/2018 11:41:52] "GET /static/js/bootstrap.min.js HTTP/1.0" 200 29110
[23/Mar/2018 11:41:52] "GET /static/js/jquery-1.10.2.min.js HTTP/1.0" 200 93107
[23/Mar/2018 11:41:52] "GET /static/css/bootstrap.css HTTP/1.0" 200 121220
Not Found: /favicon.ico
[23/Mar/2018 11:41:53] "GET /favicon.ico HTTP/1.0" 404 2543
[23/Mar/2018 11:41:56] "GET / HTTP/1.0" 200 8330
[23/Mar/2018 11:41:56] "GET / HTTP/1.0" 200 8330
[23/Mar/2018 11:41:56] "GET / HTTP/1.0" 200 8330
[23/Mar/2018 11:41:56] "GET / HTTP/1.0" 200 8330
[23/Mar/2018 11:41:56] "GET / HTTP/1.0" 200 8330
[23/Mar/2018 11:41:56] "GET / HTTP/1.0" 200 8330
[23/Mar/2018 11:41:57] "GET / HTTP/1.0" 200 8330
[23/Mar/2018 11:41:57] "GET / HTTP/1.0" 200 8330
[23/Mar/2018 11:41:57] "GET / HTTP/1.0" 200 8330
[23/Mar/2018 11:41:57] "GET / HTTP/1.0" 200 8330
[23/Mar/2018 11:41:57] "GET / HTTP/1.0" 200 8330
[23/Mar/2018 11:42:30] "POST /new_web/update_stream HTTP/1.0" 200 52
