[23/Mar/2018 08:45:18] "GET / HTTP/1.0" 200 8330
[23/Mar/2018 08:45:19] "GET / HTTP/1.0" 200 8330
[23/Mar/2018 08:45:19] "GET / HTTP/1.0" 200 8330
[23/Mar/2018 08:45:19] "GET / HTTP/1.0" 200 8330
[23/Mar/2018 08:45:19] "GET / HTTP/1.0" 200 8330
[23/Mar/2018 08:45:41] "POST /new_web/zc HTTP/1.0" 200 93
[23/Mar/2018 08:45:54] "POST /new_web/bd_sj HTTP/1.0" 200 82
[23/Mar/2018 08:46:13] "GET / HTTP/1.0" 200 8330
Performing system checks...

System check identified no issues (0 silenced).
March 23, 2018 - 08:45:05
Django version 2.0.3, using settings 'project.settings'
Starting development server at http://10.10.23.14:9999/
Quit the server with CONTROL-C.
Performing system checks...

System check identified no issues (0 silenced).
March 23, 2018 - 08:55:13
Django version 2.0.3, using settings 'project.settings'
Starting development server at http://10.10.23.14:9999/
Quit the server with CONTROL-C.
Unhandled exception in thread started by <function check_errors.<locals>.wrapper at 0x7f8b2036a9d8>
Traceback (most recent call last):
  File "/usr/local/python3/lib/python3.6/site-packages/django/utils/autoreload.py", line 225, in wrapper
    fn(*args, **kwargs)
  File "/usr/local/python3/lib/python3.6/site-packages/django/core/management/commands/runserver.py", line 120, in inner_run
    self.check(display_num_errors=True)
  File "/usr/local/python3/lib/python3.6/site-packages/django/core/management/base.py", line 364, in check
    include_deployment_checks=include_deployment_checks,
  File "/usr/local/python3/lib/python3.6/site-packages/django/core/management/base.py", line 351, in _run_checks
    return checks.run_checks(**kwargs)
  File "/usr/local/python3/lib/python3.6/site-packages/django/core/checks/registry.py", line 73, in run_checks
    new_errors = check(app_configs=app_configs)
  File "/usr/local/python3/lib/python3.6/site-packages/django/core/checks/urls.py", line 13, in check_url_config
    return check_resolver(resolver)
  File "/usr/local/python3/lib/python3.6/site-packages/django/core/checks/urls.py", line 23, in check_resolver
    return check_method()
  File "/usr/local/python3/lib/python3.6/site-packages/django/urls/resolvers.py", line 397, in check
    for pattern in self.url_patterns:
  File "/usr/local/python3/lib/python3.6/site-packages/django/utils/functional.py", line 36, in __get__
    res = instance.__dict__[self.name] = self.func(instance)
  File "/usr/local/python3/lib/python3.6/site-packages/django/urls/resolvers.py", line 536, in url_patterns
    patterns = getattr(self.urlconf_module, "urlpatterns", self.urlconf_module)
  File "/usr/local/python3/lib/python3.6/site-packages/django/utils/functional.py", line 36, in __get__
    res = instance.__dict__[self.name] = self.func(instance)
  File "/usr/local/python3/lib/python3.6/site-packages/django/urls/resolvers.py", line 529, in urlconf_module
    return import_module(self.urlconf_name)
  File "/usr/local/python3/lib/python3.6/importlib/__init__.py", line 126, in import_module
    return _bootstrap._gcd_import(name[level:], package, level)
  File "<frozen importlib._bootstrap>", line 994, in _gcd_import
  File "<frozen importlib._bootstrap>", line 971, in _find_and_load
  File "<frozen importlib._bootstrap>", line 955, in _find_and_load_unlocked
  File "<frozen importlib._bootstrap>", line 665, in _load_unlocked
  File "<frozen importlib._bootstrap_external>", line 678, in exec_module
  File "<frozen importlib._bootstrap>", line 219, in _call_with_frames_removed
  File "/home/lxy/share/django/project/project/urls.py", line 18, in <module>
    from app import views as app_views
  File "/home/lxy/share/django/project/app/views.py", line 5, in <module>
    from common.common import Common
  File "/home/lxy/share/common/common.py", line 247
    key_username = 
                  ^
SyntaxError: invalid syntax
Performing system checks...

Performing system checks...

System check identified no issues (0 silenced).
March 23, 2018 - 08:56:39
Django version 2.0.3, using settings 'project.settings'
Starting development server at http://10.10.23.14:9999/
Quit the server with CONTROL-C.
Performing system checks...

System check identified no issues (0 silenced).
March 23, 2018 - 08:56:47
Django version 2.0.3, using settings 'project.settings'
Starting development server at http://10.10.23.14:9999/
Quit the server with CONTROL-C.
Performing system checks...

System check identified no issues (0 silenced).
March 23, 2018 - 08:56:50
Django version 2.0.3, using settings 'project.settings'
Starting development server at http://10.10.23.14:9999/
Quit the server with CONTROL-C.
Performing system checks...

System check identified no issues (0 silenced).
March 23, 2018 - 08:56:58
Django version 2.0.3, using settings 'project.settings'
Starting development server at http://10.10.23.14:9999/
Quit the server with CONTROL-C.
Unhandled exception in thread started by <function check_errors.<locals>.wrapper at 0x7f1e2354b9d8>
Traceback (most recent call last):
  File "/usr/local/python3/lib/python3.6/site-packages/django/utils/autoreload.py", line 225, in wrapper
    fn(*args, **kwargs)
  File "/usr/local/python3/lib/python3.6/site-packages/django/core/management/commands/runserver.py", line 120, in inner_run
    self.check(display_num_errors=True)
  File "/usr/local/python3/lib/python3.6/site-packages/django/core/management/base.py", line 364, in check
    include_deployment_checks=include_deployment_checks,
  File "/usr/local/python3/lib/python3.6/site-packages/django/core/management/base.py", line 351, in _run_checks
    return checks.run_checks(**kwargs)
  File "/usr/local/python3/lib/python3.6/site-packages/django/core/checks/registry.py", line 73, in run_checks
    new_errors = check(app_configs=app_configs)
  File "/usr/local/python3/lib/python3.6/site-packages/django/core/checks/urls.py", line 13, in check_url_config
    return check_resolver(resolver)
  File "/usr/local/python3/lib/python3.6/site-packages/django/core/checks/urls.py", line 23, in check_resolver
    return check_method()
  File "/usr/local/python3/lib/python3.6/site-packages/django/urls/resolvers.py", line 397, in check
    for pattern in self.url_patterns:
  File "/usr/local/python3/lib/python3.6/site-packages/django/utils/functional.py", line 36, in __get__
    res = instance.__dict__[self.name] = self.func(instance)
  File "/usr/local/python3/lib/python3.6/site-packages/django/urls/resolvers.py", line 536, in url_patterns
    patterns = getattr(self.urlconf_module, "urlpatterns", self.urlconf_module)
  File "/usr/local/python3/lib/python3.6/site-packages/django/utils/functional.py", line 36, in __get__
    res = instance.__dict__[self.name] = self.func(instance)
  File "/usr/local/python3/lib/python3.6/site-packages/django/urls/resolvers.py", line 529, in urlconf_module
    return import_module(self.urlconf_name)
  File "/usr/local/python3/lib/python3.6/importlib/__init__.py", line 126, in import_module
    return _bootstrap._gcd_import(name[level:], package, level)
  File "<frozen importlib._bootstrap>", line 994, in _gcd_import
  File "<frozen importlib._bootstrap>", line 971, in _find_and_load
  File "<frozen importlib._bootstrap>", line 955, in _find_and_load_unlocked
  File "<frozen importlib._bootstrap>", line 665, in _load_unlocked
  File "<frozen importlib._bootstrap_external>", line 678, in exec_module
  File "<frozen importlib._bootstrap>", line 219, in _call_with_frames_removed
  File "/home/lxy/share/django/project/project/urls.py", line 18, in <module>
    from app import views as app_views
  File "/home/lxy/share/django/project/app/views.py", line 5, in <module>
    from common.common import Common
  File "/home/lxy/share/common/common.py", line 132
    @staticmethod
    ^
IndentationError: expected an indented block
Performing system checks...

Unhandled exception in thread started by <function check_errors.<locals>.wrapper at 0x7fa5b0a6a9d8>
Traceback (most recent call last):
  File "/usr/local/python3/lib/python3.6/site-packages/django/utils/autoreload.py", line 225, in wrapper
    fn(*args, **kwargs)
  File "/usr/local/python3/lib/python3.6/site-packages/django/core/management/commands/runserver.py", line 120, in inner_run
    self.check(display_num_errors=True)
  File "/usr/local/python3/lib/python3.6/site-packages/django/core/management/base.py", line 364, in check
    include_deployment_checks=include_deployment_checks,
  File "/usr/local/python3/lib/python3.6/site-packages/django/core/management/base.py", line 351, in _run_checks
    return checks.run_checks(**kwargs)
  File "/usr/local/python3/lib/python3.6/site-packages/django/core/checks/registry.py", line 73, in run_checks
    new_errors = check(app_configs=app_configs)
  File "/usr/local/python3/lib/python3.6/site-packages/django/core/checks/urls.py", line 13, in check_url_config
    return check_resolver(resolver)
  File "/usr/local/python3/lib/python3.6/site-packages/django/core/checks/urls.py", line 23, in check_resolver
    return check_method()
  File "/usr/local/python3/lib/python3.6/site-packages/django/urls/resolvers.py", line 397, in check
    for pattern in self.url_patterns:
  File "/usr/local/python3/lib/python3.6/site-packages/django/utils/functional.py", line 36, in __get__
    res = instance.__dict__[self.name] = self.func(instance)
  File "/usr/local/python3/lib/python3.6/site-packages/django/urls/resolvers.py", line 536, in url_patterns
    patterns = getattr(self.urlconf_module, "urlpatterns", self.urlconf_module)
  File "/usr/local/python3/lib/python3.6/site-packages/django/utils/functional.py", line 36, in __get__
    res = instance.__dict__[self.name] = self.func(instance)
  File "/usr/local/python3/lib/python3.6/site-packages/django/urls/resolvers.py", line 529, in urlconf_module
    return import_module(self.urlconf_name)
  File "/usr/local/python3/lib/python3.6/importlib/__init__.py", line 126, in import_module
    return _bootstrap._gcd_import(name[level:], package, level)
  File "<frozen importlib._bootstrap>", line 994, in _gcd_import
  File "<frozen importlib._bootstrap>", line 971, in _find_and_load
  File "<frozen importlib._bootstrap>", line 955, in _find_and_load_unlocked
  File "<frozen importlib._bootstrap>", line 665, in _load_unlocked
  File "<frozen importlib._bootstrap_external>", line 678, in exec_module
  File "<frozen importlib._bootstrap>", line 219, in _call_with_frames_removed
  File "/home/lxy/share/django/project/project/urls.py", line 18, in <module>
    from app import views as app_views
  File "/home/lxy/share/django/project/app/views.py", line 5, in <module>
    from common.common import Common
  File "/home/lxy/share/common/common.py", line 132
    @staticmethod
    ^
IndentationError: expected an indented block
Performing system checks...

Performing system checks...

System check identified no issues (0 silenced).
March 23, 2018 - 08:58:30
Django version 2.0.3, using settings 'project.settings'
Starting development server at http://10.10.23.14:9999/
Quit the server with CONTROL-C.
Performing system checks...

System check identified no issues (0 silenced).
March 23, 2018 - 08:58:37
Django version 2.0.3, using settings 'project.settings'
Starting development server at http://10.10.23.14:9999/
Quit the server with CONTROL-C.
Performing system checks...

System check identified no issues (0 silenced).
March 23, 2018 - 08:58:53
Django version 2.0.3, using settings 'project.settings'
Starting development server at http://10.10.23.14:9999/
Quit the server with CONTROL-C.
Performing system checks...

System check identified no issues (0 silenced).
March 23, 2018 - 08:59:27
Django version 2.0.3, using settings 'project.settings'
Starting development server at http://10.10.23.14:9999/
Quit the server with CONTROL-C.
Performing system checks...

System check identified no issues (0 silenced).
March 23, 2018 - 08:59:48
Django version 2.0.3, using settings 'project.settings'
Starting development server at http://10.10.23.14:9999/
Quit the server with CONTROL-C.
Performing system checks...

System check identified no issues (0 silenced).
March 23, 2018 - 09:00:52
Django version 2.0.3, using settings 'project.settings'
Starting development server at http://10.10.23.14:9999/
Quit the server with CONTROL-C.
Performing system checks...

System check identified no issues (0 silenced).
March 23, 2018 - 09:00:58
Django version 2.0.3, using settings 'project.settings'
Starting development server at http://10.10.23.14:9999/
Quit the server with CONTROL-C.
Performing system checks...

System check identified no issues (0 silenced).
March 23, 2018 - 09:01:06
Django version 2.0.3, using settings 'project.settings'
Starting development server at http://10.10.23.14:9999/
Quit the server with CONTROL-C.
Performing system checks...

System check identified no issues (0 silenced).
March 23, 2018 - 09:01:09
Django version 2.0.3, using settings 'project.settings'
Starting development server at http://10.10.23.14:9999/
Quit the server with CONTROL-C.
Performing system checks...

System check identified no issues (0 silenced).
March 23, 2018 - 09:01:24
Django version 2.0.3, using settings 'project.settings'
Starting development server at http://10.10.23.14:9999/
Quit the server with CONTROL-C.
Unhandled exception in thread started by <function check_errors.<locals>.wrapper at 0x7fe0baf149d8>
Traceback (most recent call last):
  File "/usr/local/python3/lib/python3.6/site-packages/django/utils/autoreload.py", line 225, in wrapper
    fn(*args, **kwargs)
  File "/usr/local/python3/lib/python3.6/site-packages/django/core/management/commands/runserver.py", line 120, in inner_run
    self.check(display_num_errors=True)
  File "/usr/local/python3/lib/python3.6/site-packages/django/core/management/base.py", line 364, in check
    include_deployment_checks=include_deployment_checks,
  File "/usr/local/python3/lib/python3.6/site-packages/django/core/management/base.py", line 351, in _run_checks
    return checks.run_checks(**kwargs)
  File "/usr/local/python3/lib/python3.6/site-packages/django/core/checks/registry.py", line 73, in run_checks
    new_errors = check(app_configs=app_configs)
  File "/usr/local/python3/lib/python3.6/site-packages/django/core/checks/urls.py", line 13, in check_url_config
    return check_resolver(resolver)
  File "/usr/local/python3/lib/python3.6/site-packages/django/core/checks/urls.py", line 23, in check_resolver
    return check_method()
  File "/usr/local/python3/lib/python3.6/site-packages/django/urls/resolvers.py", line 397, in check
    for pattern in self.url_patterns:
  File "/usr/local/python3/lib/python3.6/site-packages/django/utils/functional.py", line 36, in __get__
    res = instance.__dict__[self.name] = self.func(instance)
  File "/usr/local/python3/lib/python3.6/site-packages/django/urls/resolvers.py", line 536, in url_patterns
    patterns = getattr(self.urlconf_module, "urlpatterns", self.urlconf_module)
  File "/usr/local/python3/lib/python3.6/site-packages/django/utils/functional.py", line 36, in __get__
    res = instance.__dict__[self.name] = self.func(instance)
  File "/usr/local/python3/lib/python3.6/site-packages/django/urls/resolvers.py", line 529, in urlconf_module
    return import_module(self.urlconf_name)
  File "/usr/local/python3/lib/python3.6/importlib/__init__.py", line 126, in import_module
    return _bootstrap._gcd_import(name[level:], package, level)
  File "<frozen importlib._bootstrap>", line 994, in _gcd_import
  File "<frozen importlib._bootstrap>", line 971, in _find_and_load
  File "<frozen importlib._bootstrap>", line 955, in _find_and_load_unlocked
  File "<frozen importlib._bootstrap>", line 665, in _load_unlocked
  File "<frozen importlib._bootstrap_external>", line 678, in exec_module
  File "<frozen importlib._bootstrap>", line 219, in _call_with_frames_removed
  File "/home/lxy/share/django/project/project/urls.py", line 18, in <module>
    from app import views as app_views
  File "/home/lxy/share/django/project/app/views.py", line 5, in <module>
    from common.common import Common
  File "/home/lxy/share/common/common.py", line 253
    key_username = 'hm_user_name_redis_prefix:{}'.format(Common.md5()username)
                                                                            ^
SyntaxError: invalid syntax
Performing system checks...

Performing system checks...

System check identified no issues (0 silenced).
March 23, 2018 - 09:02:14
Django version 2.0.3, using settings 'project.settings'
Starting development server at http://10.10.23.14:9999/
Quit the server with CONTROL-C.
[23/Mar/2018 09:03:07] "GET / HTTP/1.0" 200 8330
Performing system checks...

System check identified no issues (0 silenced).
March 23, 2018 - 09:02:41
Django version 2.0.3, using settings 'project.settings'
Starting development server at http://10.10.23.14:9999/
Quit the server with CONTROL-C.
Performing system checks...

System check identified no issues (0 silenced).
March 23, 2018 - 09:04:49
Django version 2.0.3, using settings 'project.settings'
Starting development server at http://10.10.23.14:9999/
Quit the server with CONTROL-C.
Performing system checks...

System check identified no issues (0 silenced).
March 23, 2018 - 09:05:54
Django version 2.0.3, using settings 'project.settings'
Starting development server at http://10.10.23.14:9999/
Quit the server with CONTROL-C.
Performing system checks...

System check identified no issues (0 silenced).
March 23, 2018 - 09:06:03
Django version 2.0.3, using settings 'project.settings'
Starting development server at http://10.10.23.14:9999/
Quit the server with CONTROL-C.
Performing system checks...

System check identified no issues (0 silenced).
March 23, 2018 - 09:06:12
Django version 2.0.3, using settings 'project.settings'
Starting development server at http://10.10.23.14:9999/
Quit the server with CONTROL-C.
Performing system checks...

System check identified no issues (0 silenced).
March 23, 2018 - 09:06:25
Django version 2.0.3, using settings 'project.settings'
Starting development server at http://10.10.23.14:9999/
Quit the server with CONTROL-C.
Performing system checks...

System check identified no issues (0 silenced).
March 23, 2018 - 09:06:36
Django version 2.0.3, using settings 'project.settings'
Starting development server at http://10.10.23.14:9999/
Quit the server with CONTROL-C.
Unhandled exception in thread started by <function check_errors.<locals>.wrapper at 0x7f084e4f09d8>
Traceback (most recent call last):
  File "/usr/local/python3/lib/python3.6/site-packages/django/utils/autoreload.py", line 225, in wrapper
    fn(*args, **kwargs)
  File "/usr/local/python3/lib/python3.6/site-packages/django/core/management/commands/runserver.py", line 120, in inner_run
    self.check(display_num_errors=True)
  File "/usr/local/python3/lib/python3.6/site-packages/django/core/management/base.py", line 364, in check
    include_deployment_checks=include_deployment_checks,
  File "/usr/local/python3/lib/python3.6/site-packages/django/core/management/base.py", line 351, in _run_checks
    return checks.run_checks(**kwargs)
  File "/usr/local/python3/lib/python3.6/site-packages/django/core/checks/registry.py", line 73, in run_checks
    new_errors = check(app_configs=app_configs)
  File "/usr/local/python3/lib/python3.6/site-packages/django/core/checks/urls.py", line 13, in check_url_config
    return check_resolver(resolver)
  File "/usr/local/python3/lib/python3.6/site-packages/django/core/checks/urls.py", line 23, in check_resolver
    return check_method()
  File "/usr/local/python3/lib/python3.6/site-packages/django/urls/resolvers.py", line 397, in check
    for pattern in self.url_patterns:
  File "/usr/local/python3/lib/python3.6/site-packages/django/utils/functional.py", line 36, in __get__
    res = instance.__dict__[self.name] = self.func(instance)
  File "/usr/local/python3/lib/python3.6/site-packages/django/urls/resolvers.py", line 536, in url_patterns
    patterns = getattr(self.urlconf_module, "urlpatterns", self.urlconf_module)
  File "/usr/local/python3/lib/python3.6/site-packages/django/utils/functional.py", line 36, in __get__
    res = instance.__dict__[self.name] = self.func(instance)
  File "/usr/local/python3/lib/python3.6/site-packages/django/urls/resolvers.py", line 529, in urlconf_module
    return import_module(self.urlconf_name)
  File "/usr/local/python3/lib/python3.6/importlib/__init__.py", line 126, in import_module
    return _bootstrap._gcd_import(name[level:], package, level)
  File "<frozen importlib._bootstrap>", line 994, in _gcd_import
  File "<frozen importlib._bootstrap>", line 971, in _find_and_load
  File "<frozen importlib._bootstrap>", line 955, in _find_and_load_unlocked
  File "<frozen importlib._bootstrap>", line 665, in _load_unlocked
  File "<frozen importlib._bootstrap_external>", line 678, in exec_module
  File "<frozen importlib._bootstrap>", line 219, in _call_with_frames_removed
  File "/home/lxy/share/django/project/project/urls.py", line 18, in <module>
    from app import views as app_views
  File "/home/lxy/share/django/project/app/views.py", line 5, in <module>
    from common.common import Common
  File "/home/lxy/share/common/common.py", line 256
    print(ret)
        ^
IndentationError: expected an indented block
Performing system checks...

Performing system checks...

System check identified no issues (0 silenced).
March 23, 2018 - 09:07:04
Django version 2.0.3, using settings 'project.settings'
Starting development server at http://10.10.23.14:9999/
Quit the server with CONTROL-C.
Performing system checks...

System check identified no issues (0 silenced).
March 23, 2018 - 09:07:54
Django version 2.0.3, using settings 'project.settings'
Starting development server at http://10.10.23.14:9999/
Quit the server with CONTROL-C.
Performing system checks...

System check identified no issues (0 silenced).
March 23, 2018 - 09:08:03
Django version 2.0.3, using settings 'project.settings'
Starting development server at http://10.10.23.14:9999/
Quit the server with CONTROL-C.
Unhandled exception in thread started by <function check_errors.<locals>.wrapper at 0x7f9075edd9d8>
Traceback (most recent call last):
  File "/usr/local/python3/lib/python3.6/site-packages/django/utils/autoreload.py", line 225, in wrapper
    fn(*args, **kwargs)
  File "/usr/local/python3/lib/python3.6/site-packages/django/core/management/commands/runserver.py", line 120, in inner_run
    self.check(display_num_errors=True)
  File "/usr/local/python3/lib/python3.6/site-packages/django/core/management/base.py", line 364, in check
    include_deployment_checks=include_deployment_checks,
  File "/usr/local/python3/lib/python3.6/site-packages/django/core/management/base.py", line 351, in _run_checks
    return checks.run_checks(**kwargs)
  File "/usr/local/python3/lib/python3.6/site-packages/django/core/checks/registry.py", line 73, in run_checks
    new_errors = check(app_configs=app_configs)
  File "/usr/local/python3/lib/python3.6/site-packages/django/core/checks/urls.py", line 13, in check_url_config
    return check_resolver(resolver)
  File "/usr/local/python3/lib/python3.6/site-packages/django/core/checks/urls.py", line 23, in check_resolver
    return check_method()
  File "/usr/local/python3/lib/python3.6/site-packages/django/urls/resolvers.py", line 397, in check
    for pattern in self.url_patterns:
  File "/usr/local/python3/lib/python3.6/site-packages/django/utils/functional.py", line 36, in __get__
    res = instance.__dict__[self.name] = self.func(instance)
  File "/usr/local/python3/lib/python3.6/site-packages/django/urls/resolvers.py", line 536, in url_patterns
    patterns = getattr(self.urlconf_module, "urlpatterns", self.urlconf_module)
  File "/usr/local/python3/lib/python3.6/site-packages/django/utils/functional.py", line 36, in __get__
    res = instance.__dict__[self.name] = self.func(instance)
  File "/usr/local/python3/lib/python3.6/site-packages/django/urls/resolvers.py", line 529, in urlconf_module
    return import_module(self.urlconf_name)
  File "/usr/local/python3/lib/python3.6/importlib/__init__.py", line 126, in import_module
    return _bootstrap._gcd_import(name[level:], package, level)
  File "<frozen importlib._bootstrap>", line 994, in _gcd_import
  File "<frozen importlib._bootstrap>", line 971, in _find_and_load
  File "<frozen importlib._bootstrap>", line 955, in _find_and_load_unlocked
  File "<frozen importlib._bootstrap>", line 665, in _load_unlocked
  File "<frozen importlib._bootstrap_external>", line 678, in exec_module
  File "<frozen importlib._bootstrap>", line 219, in _call_with_frames_removed
  File "/home/lxy/share/django/project/project/urls.py", line 18, in <module>
    from app import views as app_views
  File "/home/lxy/share/django/project/app/views.py", line 5, in <module>
    from common.common import Common
  File "/home/lxy/share/common/common.py", line 255
    if not Common.REDIS_INST.get(key_username) and UserName.:
                                                            ^
SyntaxError: invalid syntax
Performing system checks...

Performing system checks...

System check identified no issues (0 silenced).
March 23, 2018 - 09:09:10
Django version 2.0.3, using settings 'project.settings'
Starting development server at http://10.10.23.14:9999/
Quit the server with CONTROL-C.
Performing system checks...

System check identified no issues (0 silenced).
March 23, 2018 - 09:09:48
Django version 2.0.3, using settings 'project.settings'
Starting development server at http://10.10.23.14:9999/
Quit the server with CONTROL-C.
[23/Mar/2018 09:19:30] "GET / HTTP/1.0" 200 8330
[23/Mar/2018 09:19:30] "GET /static/js/jquery-1.10.2.min.js HTTP/1.0" 200 93107
[23/Mar/2018 09:19:30] "GET /static/js/bootstrap.min.js HTTP/1.0" 200 29110
[23/Mar/2018 09:19:30] "GET /static/css/bootstrap.css HTTP/1.0" 200 121220
[23/Mar/2018 09:19:30] "GET /static/js/lucky.js HTTP/1.0" 200 1789
Not Found: /favicon.ico
[23/Mar/2018 09:19:30] "GET /favicon.ico HTTP/1.0" 404 2543
[23/Mar/2018 09:20:15] "GET /static/css/bootstrap.css.map HTTP/1.0" 404 1701
Not Found: /favicon.ico
[23/Mar/2018 09:47:10] "GET /favicon.ico HTTP/1.0" 404 2543
Not Found: /favicon.ico
[23/Mar/2018 09:47:10] "GET /favicon.ico HTTP/1.0" 404 2543
Not Found: /favicon.ico
[23/Mar/2018 09:47:10] "GET /favicon.ico HTTP/1.0" 404 2543
Not Found: /favicon.ico
[23/Mar/2018 09:47:10] "GET /favicon.ico HTTP/1.0" 404 2543
Not Found: /favicon.ico
[23/Mar/2018 09:47:10] "GET /favicon.ico HTTP/1.0" 404 2543
Not Found: /favicon.ico
[23/Mar/2018 09:47:10] "GET /favicon.ico HTTP/1.0" 404 2543
Not Found: /favicon.ico
[23/Mar/2018 09:47:10] "GET /favicon.ico HTTP/1.0" 404 2543
Not Found: /favicon.ico
[23/Mar/2018 09:47:10] "GET /favicon.ico HTTP/1.0" 404 2543
Not Found: /favicon.ico
[23/Mar/2018 09:51:27] "GET /favicon.ico HTTP/1.0" 404 2543
Not Found: /favicon.ico
[23/Mar/2018 09:51:27] "GET /favicon.ico HTTP/1.0" 404 2543
Not Found: /favicon.ico
[23/Mar/2018 09:51:27] "GET /favicon.ico HTTP/1.0" 404 2543
Not Found: /favicon.ico
[23/Mar/2018 09:51:27] "GET /favicon.ico HTTP/1.0" 404 2543
Not Found: /favicon.ico
[23/Mar/2018 10:29:52] "GET /favicon.ico HTTP/1.0" 404 2543
[23/Mar/2018 11:41:52] "GET / HTTP/1.0" 200 8330
[23/Mar/2018 11:41:52] "GET /static/js/lucky.js HTTP/1.0" 200 1789
[23/Mar/2018 11:41:52] "GET /static/js/bootstrap.min.js HTTP/1.0" 200 29110
[23/Mar/2018 11:41:52] "GET /static/js/jquery-1.10.2.min.js HTTP/1.0" 200 93107
[23/Mar/2018 11:41:52] "GET /static/css/bootstrap.css HTTP/1.0" 200 121220
Not Found: /favicon.ico
[23/Mar/2018 11:41:53] "GET /favicon.ico HTTP/1.0" 404 2543
[23/Mar/2018 11:41:56] "GET / HTTP/1.0" 200 8330
[23/Mar/2018 11:41:56] "GET / HTTP/1.0" 200 8330
[23/Mar/2018 11:41:56] "GET / HTTP/1.0" 200 8330
[23/Mar/2018 11:41:56] "GET / HTTP/1.0" 200 8330
[23/Mar/2018 11:41:56] "GET / HTTP/1.0" 200 8330
[23/Mar/2018 11:41:56] "GET / HTTP/1.0" 200 8330
[23/Mar/2018 11:41:57] "GET / HTTP/1.0" 200 8330
[23/Mar/2018 11:41:57] "GET / HTTP/1.0" 200 8330
[23/Mar/2018 11:41:57] "GET / HTTP/1.0" 200 8330
[23/Mar/2018 11:41:57] "GET / HTTP/1.0" 200 8330
[23/Mar/2018 11:41:57] "GET / HTTP/1.0" 200 8330
[23/Mar/2018 11:42:30] "POST /new_web/update_stream HTTP/1.0" 200 52
[26/Mar/2018 02:13:38] "GET / HTTP/1.0" 200 8330
[26/Mar/2018 02:13:38] "GET /static/js/bootstrap.min.js HTTP/1.0" 304 0
[26/Mar/2018 02:13:38] "GET /static/js/jquery-1.10.2.min.js HTTP/1.0" 304 0
[26/Mar/2018 02:13:38] "GET /static/css/bootstrap.css HTTP/1.0" 304 0
[26/Mar/2018 02:13:38] "GET /static/js/lucky.js HTTP/1.0" 304 0
Not Found: /favicon.ico
[26/Mar/2018 02:29:28] "GET /favicon.ico HTTP/1.0" 404 2543
[26/Mar/2018 02:38:09] "GET / HTTP/1.0" 200 8330
[26/Mar/2018 02:38:09] "GET /static/js/jquery-1.10.2.min.js HTTP/1.0" 304 0
[26/Mar/2018 02:38:09] "GET /static/js/bootstrap.min.js HTTP/1.0" 304 0
[26/Mar/2018 02:38:09] "GET /static/js/lucky.js HTTP/1.0" 304 0
[26/Mar/2018 02:38:09] "GET /static/css/bootstrap.css HTTP/1.0" 200 121220
Not Found: /favicon.ico
[26/Mar/2018 02:38:10] "GET /favicon.ico HTTP/1.0" 404 2543
[26/Mar/2018 02:38:25] "POST /new_web/update_stream HTTP/1.0" 200 52
Not Found: /favicon.ico
[26/Mar/2018 02:39:53] "GET /favicon.ico HTTP/1.0" 404 2543
Performing system checks...

System check identified no issues (0 silenced).
March 23, 2018 - 09:17:44
Django version 2.0.3, using settings 'project.settings'
Starting development server at http://10.10.23.14:9999/
Quit the server with CONTROL-C.
Performing system checks...

System check identified no issues (0 silenced).
March 26, 2018 - 02:49:24
Django version 2.0.3, using settings 'project.settings'
Starting development server at http://10.10.23.14:9999/
Quit the server with CONTROL-C.
Performing system checks...

System check identified no issues (0 silenced).
March 26, 2018 - 02:49:33
Django version 2.0.3, using settings 'project.settings'
Starting development server at http://10.10.23.14:9999/
Quit the server with CONTROL-C.
Performing system checks...

System check identified no issues (0 silenced).
March 26, 2018 - 02:50:03
Django version 2.0.3, using settings 'project.settings'
Starting development server at http://10.10.23.14:9999/
Quit the server with CONTROL-C.
Performing system checks...

System check identified no issues (0 silenced).
March 26, 2018 - 02:50:42
Django version 2.0.3, using settings 'project.settings'
Starting development server at http://10.10.23.14:9999/
Quit the server with CONTROL-C.
Performing system checks...

System check identified no issues (0 silenced).
March 26, 2018 - 02:55:09
Django version 2.0.3, using settings 'project.settings'
Starting development server at http://10.10.23.14:9999/
Quit the server with CONTROL-C.
Performing system checks...

System check identified no issues (0 silenced).
March 26, 2018 - 02:55:13
Django version 2.0.3, using settings 'project.settings'
Starting development server at http://10.10.23.14:9999/
Quit the server with CONTROL-C.
Performing system checks...

System check identified no issues (0 silenced).
March 26, 2018 - 02:55:57
Django version 2.0.3, using settings 'project.settings'
Starting development server at http://10.10.23.14:9999/
Quit the server with CONTROL-C.
Performing system checks...

System check identified no issues (0 silenced).
March 26, 2018 - 02:56:43
Django version 2.0.3, using settings 'project.settings'
Starting development server at http://10.10.23.14:9999/
Quit the server with CONTROL-C.
Unhandled exception in thread started by <function check_errors.<locals>.wrapper at 0x7f51d4a5c9d8>
Traceback (most recent call last):
  File "/usr/local/python3/lib/python3.6/site-packages/django/utils/autoreload.py", line 225, in wrapper
    fn(*args, **kwargs)
  File "/usr/local/python3/lib/python3.6/site-packages/django/core/management/commands/runserver.py", line 120, in inner_run
    self.check(display_num_errors=True)
  File "/usr/local/python3/lib/python3.6/site-packages/django/core/management/base.py", line 364, in check
    include_deployment_checks=include_deployment_checks,
  File "/usr/local/python3/lib/python3.6/site-packages/django/core/management/base.py", line 351, in _run_checks
    return checks.run_checks(**kwargs)
  File "/usr/local/python3/lib/python3.6/site-packages/django/core/checks/registry.py", line 73, in run_checks
    new_errors = check(app_configs=app_configs)
  File "/usr/local/python3/lib/python3.6/site-packages/django/core/checks/urls.py", line 13, in check_url_config
    return check_resolver(resolver)
  File "/usr/local/python3/lib/python3.6/site-packages/django/core/checks/urls.py", line 23, in check_resolver
    return check_method()
  File "/usr/local/python3/lib/python3.6/site-packages/django/urls/resolvers.py", line 397, in check
    for pattern in self.url_patterns:
  File "/usr/local/python3/lib/python3.6/site-packages/django/utils/functional.py", line 36, in __get__
    res = instance.__dict__[self.name] = self.func(instance)
  File "/usr/local/python3/lib/python3.6/site-packages/django/urls/resolvers.py", line 536, in url_patterns
    patterns = getattr(self.urlconf_module, "urlpatterns", self.urlconf_module)
  File "/usr/local/python3/lib/python3.6/site-packages/django/utils/functional.py", line 36, in __get__
    res = instance.__dict__[self.name] = self.func(instance)
  File "/usr/local/python3/lib/python3.6/site-packages/django/urls/resolvers.py", line 529, in urlconf_module
    return import_module(self.urlconf_name)
  File "/usr/local/python3/lib/python3.6/importlib/__init__.py", line 126, in import_module
    return _bootstrap._gcd_import(name[level:], package, level)
  File "<frozen importlib._bootstrap>", line 994, in _gcd_import
  File "<frozen importlib._bootstrap>", line 971, in _find_and_load
  File "<frozen importlib._bootstrap>", line 955, in _find_and_load_unlocked
  File "<frozen importlib._bootstrap>", line 665, in _load_unlocked
  File "<frozen importlib._bootstrap_external>", line 678, in exec_module
  File "<frozen importlib._bootstrap>", line 219, in _call_with_frames_removed
  File "/home/lxy/share/django/project/project/urls.py", line 18, in <module>
    from app import views as app_views
  File "/home/lxy/share/django/project/app/views.py", line 5, in <module>
    from common.common import Common
  File "/home/lxy/share/common/common.py", line 265
    UserName.
            ^
SyntaxError: invalid syntax
Performing system checks...

Performing system checks...

System check identified no issues (0 silenced).
March 26, 2018 - 02:57:38
Django version 2.0.3, using settings 'project.settings'
Starting development server at http://10.10.23.14:9999/
Quit the server with CONTROL-C.
Performing system checks...

System check identified no issues (0 silenced).
March 26, 2018 - 02:57:59
Django version 2.0.3, using settings 'project.settings'
Starting development server at http://10.10.23.14:9999/
Quit the server with CONTROL-C.
Performing system checks...

System check identified no issues (0 silenced).
March 26, 2018 - 02:58:43
Django version 2.0.3, using settings 'project.settings'
Starting development server at http://10.10.23.14:9999/
Quit the server with CONTROL-C.
Performing system checks...

System check identified no issues (0 silenced).
March 26, 2018 - 02:58:53
Django version 2.0.3, using settings 'project.settings'
Starting development server at http://10.10.23.14:9999/
Quit the server with CONTROL-C.
Performing system checks...

System check identified no issues (0 silenced).
March 26, 2018 - 02:59:35
Django version 2.0.3, using settings 'project.settings'
Starting development server at http://10.10.23.14:9999/
Quit the server with CONTROL-C.
Performing system checks...

System check identified no issues (0 silenced).
March 26, 2018 - 02:59:43
Django version 2.0.3, using settings 'project.settings'
Starting development server at http://10.10.23.14:9999/
Quit the server with CONTROL-C.
Unhandled exception in thread started by <function check_errors.<locals>.wrapper at 0x7f0fc4e879d8>
Traceback (most recent call last):
  File "/usr/local/python3/lib/python3.6/site-packages/django/utils/autoreload.py", line 225, in wrapper
    fn(*args, **kwargs)
  File "/usr/local/python3/lib/python3.6/site-packages/django/core/management/commands/runserver.py", line 120, in inner_run
    self.check(display_num_errors=True)
  File "/usr/local/python3/lib/python3.6/site-packages/django/core/management/base.py", line 364, in check
    include_deployment_checks=include_deployment_checks,
  File "/usr/local/python3/lib/python3.6/site-packages/django/core/management/base.py", line 351, in _run_checks
    return checks.run_checks(**kwargs)
  File "/usr/local/python3/lib/python3.6/site-packages/django/core/checks/registry.py", line 73, in run_checks
    new_errors = check(app_configs=app_configs)
  File "/usr/local/python3/lib/python3.6/site-packages/django/core/checks/urls.py", line 13, in check_url_config
    return check_resolver(resolver)
  File "/usr/local/python3/lib/python3.6/site-packages/django/core/checks/urls.py", line 23, in check_resolver
    return check_method()
  File "/usr/local/python3/lib/python3.6/site-packages/django/urls/resolvers.py", line 397, in check
    for pattern in self.url_patterns:
  File "/usr/local/python3/lib/python3.6/site-packages/django/utils/functional.py", line 36, in __get__
    res = instance.__dict__[self.name] = self.func(instance)
  File "/usr/local/python3/lib/python3.6/site-packages/django/urls/resolvers.py", line 536, in url_patterns
    patterns = getattr(self.urlconf_module, "urlpatterns", self.urlconf_module)
  File "/usr/local/python3/lib/python3.6/site-packages/django/utils/functional.py", line 36, in __get__
    res = instance.__dict__[self.name] = self.func(instance)
  File "/usr/local/python3/lib/python3.6/site-packages/django/urls/resolvers.py", line 529, in urlconf_module
    return import_module(self.urlconf_name)
  File "/usr/local/python3/lib/python3.6/importlib/__init__.py", line 126, in import_module
    return _bootstrap._gcd_import(name[level:], package, level)
  File "<frozen importlib._bootstrap>", line 994, in _gcd_import
  File "<frozen importlib._bootstrap>", line 971, in _find_and_load
  File "<frozen importlib._bootstrap>", line 955, in _find_and_load_unlocked
  File "<frozen importlib._bootstrap>", line 665, in _load_unlocked
  File "<frozen importlib._bootstrap_external>", line 678, in exec_module
  File "<frozen importlib._bootstrap>", line 219, in _call_with_frames_removed
  File "/home/lxy/share/django/project/project/urls.py", line 18, in <module>
    from app import views as app_views
  File "/home/lxy/share/django/project/app/views.py", line 5, in <module>
    from common.common import Common
  File "/home/lxy/share/common/common.py", line 267
    Userinfo.create(uid=uid,password=)
                                     ^
SyntaxError: invalid syntax
Performing system checks...

Performing system checks...

System check identified no issues (0 silenced).
March 26, 2018 - 03:00:26
Django version 2.0.3, using settings 'project.settings'
Starting development server at http://10.10.23.14:9999/
Quit the server with CONTROL-C.
Unhandled exception in thread started by <function check_errors.<locals>.wrapper at 0x7f7eb14de9d8>
Traceback (most recent call last):
  File "/usr/local/python3/lib/python3.6/site-packages/django/utils/autoreload.py", line 225, in wrapper
    fn(*args, **kwargs)
  File "/usr/local/python3/lib/python3.6/site-packages/django/core/management/commands/runserver.py", line 120, in inner_run
    self.check(display_num_errors=True)
  File "/usr/local/python3/lib/python3.6/site-packages/django/core/management/base.py", line 364, in check
    include_deployment_checks=include_deployment_checks,
  File "/usr/local/python3/lib/python3.6/site-packages/django/core/management/base.py", line 351, in _run_checks
    return checks.run_checks(**kwargs)
  File "/usr/local/python3/lib/python3.6/site-packages/django/core/checks/registry.py", line 73, in run_checks
    new_errors = check(app_configs=app_configs)
  File "/usr/local/python3/lib/python3.6/site-packages/django/core/checks/urls.py", line 13, in check_url_config
    return check_resolver(resolver)
  File "/usr/local/python3/lib/python3.6/site-packages/django/core/checks/urls.py", line 23, in check_resolver
    return check_method()
  File "/usr/local/python3/lib/python3.6/site-packages/django/urls/resolvers.py", line 397, in check
    for pattern in self.url_patterns:
  File "/usr/local/python3/lib/python3.6/site-packages/django/utils/functional.py", line 36, in __get__
    res = instance.__dict__[self.name] = self.func(instance)
  File "/usr/local/python3/lib/python3.6/site-packages/django/urls/resolvers.py", line 536, in url_patterns
    patterns = getattr(self.urlconf_module, "urlpatterns", self.urlconf_module)
  File "/usr/local/python3/lib/python3.6/site-packages/django/utils/functional.py", line 36, in __get__
    res = instance.__dict__[self.name] = self.func(instance)
  File "/usr/local/python3/lib/python3.6/site-packages/django/urls/resolvers.py", line 529, in urlconf_module
    return import_module(self.urlconf_name)
  File "/usr/local/python3/lib/python3.6/importlib/__init__.py", line 126, in import_module
    return _bootstrap._gcd_import(name[level:], package, level)
  File "<frozen importlib._bootstrap>", line 994, in _gcd_import
  File "<frozen importlib._bootstrap>", line 971, in _find_and_load
  File "<frozen importlib._bootstrap>", line 955, in _find_and_load_unlocked
  File "<frozen importlib._bootstrap>", line 665, in _load_unlocked
  File "<frozen importlib._bootstrap_external>", line 678, in exec_module
  File "<frozen importlib._bootstrap>", line 219, in _call_with_frames_removed
  File "/home/lxy/share/django/project/project/urls.py", line 18, in <module>
    from app import views as app_views
  File "/home/lxy/share/django/project/app/views.py", line 5, in <module>
    from common.common import Common
  File "/home/lxy/share/common/common.py", line 268
    Userinfo.create(uid=uid,password=)
                                     ^
SyntaxError: invalid syntax
Performing system checks...

Performing system checks...

System check identified no issues (0 silenced).
March 26, 2018 - 03:00:50
Django version 2.0.3, using settings 'project.settings'
Starting development server at http://10.10.23.14:9999/
Quit the server with CONTROL-C.
Performing system checks...

System check identified no issues (0 silenced).
March 26, 2018 - 03:01:06
Django version 2.0.3, using settings 'project.settings'
Starting development server at http://10.10.23.14:9999/
Quit the server with CONTROL-C.
Performing system checks...

System check identified no issues (0 silenced).
March 26, 2018 - 03:01:10
Django version 2.0.3, using settings 'project.settings'
Starting development server at http://10.10.23.14:9999/
Quit the server with CONTROL-C.
Performing system checks...

System check identified no issues (0 silenced).
March 26, 2018 - 03:01:18
Django version 2.0.3, using settings 'project.settings'
Starting development server at http://10.10.23.14:9999/
Quit the server with CONTROL-C.
Performing system checks...

System check identified no issues (0 silenced).
March 26, 2018 - 03:01:23
Django version 2.0.3, using settings 'project.settings'
Starting development server at http://10.10.23.14:9999/
Quit the server with CONTROL-C.
Performing system checks...

System check identified no issues (0 silenced).
March 26, 2018 - 03:01:30
Django version 2.0.3, using settings 'project.settings'
Starting development server at http://10.10.23.14:9999/
Quit the server with CONTROL-C.
Performing system checks...

System check identified no issues (0 silenced).
March 26, 2018 - 03:14:34
Django version 2.0.3, using settings 'project.settings'
Starting development server at http://10.10.23.14:9999/
Quit the server with CONTROL-C.
Unhandled exception in thread started by <function check_errors.<locals>.wrapper at 0x7f7d2c11e9d8>
Traceback (most recent call last):
  File "/usr/local/python3/lib/python3.6/site-packages/django/utils/autoreload.py", line 225, in wrapper
    fn(*args, **kwargs)
  File "/usr/local/python3/lib/python3.6/site-packages/django/core/management/commands/runserver.py", line 120, in inner_run
    self.check(display_num_errors=True)
  File "/usr/local/python3/lib/python3.6/site-packages/django/core/management/base.py", line 364, in check
    include_deployment_checks=include_deployment_checks,
  File "/usr/local/python3/lib/python3.6/site-packages/django/core/management/base.py", line 351, in _run_checks
    return checks.run_checks(**kwargs)
  File "/usr/local/python3/lib/python3.6/site-packages/django/core/checks/registry.py", line 73, in run_checks
    new_errors = check(app_configs=app_configs)
  File "/usr/local/python3/lib/python3.6/site-packages/django/core/checks/urls.py", line 13, in check_url_config
    return check_resolver(resolver)
  File "/usr/local/python3/lib/python3.6/site-packages/django/core/checks/urls.py", line 23, in check_resolver
    return check_method()
  File "/usr/local/python3/lib/python3.6/site-packages/django/urls/resolvers.py", line 397, in check
    for pattern in self.url_patterns:
  File "/usr/local/python3/lib/python3.6/site-packages/django/utils/functional.py", line 36, in __get__
    res = instance.__dict__[self.name] = self.func(instance)
  File "/usr/local/python3/lib/python3.6/site-packages/django/urls/resolvers.py", line 536, in url_patterns
    patterns = getattr(self.urlconf_module, "urlpatterns", self.urlconf_module)
  File "/usr/local/python3/lib/python3.6/site-packages/django/utils/functional.py", line 36, in __get__
    res = instance.__dict__[self.name] = self.func(instance)
  File "/usr/local/python3/lib/python3.6/site-packages/django/urls/resolvers.py", line 529, in urlconf_module
    return import_module(self.urlconf_name)
  File "/usr/local/python3/lib/python3.6/importlib/__init__.py", line 126, in import_module
    return _bootstrap._gcd_import(name[level:], package, level)
  File "<frozen importlib._bootstrap>", line 994, in _gcd_import
  File "<frozen importlib._bootstrap>", line 971, in _find_and_load
  File "<frozen importlib._bootstrap>", line 955, in _find_and_load_unlocked
  File "<frozen importlib._bootstrap>", line 665, in _load_unlocked
  File "<frozen importlib._bootstrap_external>", line 678, in exec_module
  File "<frozen importlib._bootstrap>", line 219, in _call_with_frames_removed
  File "/home/lxy/share/django/project/project/urls.py", line 18, in <module>
    from app import views as app_views
  File "/home/lxy/share/django/project/app/views.py", line 5, in <module>
    from common.common import Common
  File "/home/lxy/share/common/common.py", line 266
    Userbase.
            ^
SyntaxError: invalid syntax
Performing system checks...

Performing system checks...

System check identified no issues (0 silenced).
March 26, 2018 - 03:15:14
Django version 2.0.3, using settings 'project.settings'
Starting development server at http://10.10.23.14:9999/
Quit the server with CONTROL-C.
Performing system checks...

System check identified no issues (0 silenced).
March 26, 2018 - 03:15:53
Django version 2.0.3, using settings 'project.settings'
Starting development server at http://10.10.23.14:9999/
Quit the server with CONTROL-C.
Performing system checks...

System check identified no issues (0 silenced).
March 26, 2018 - 03:16:01
Django version 2.0.3, using settings 'project.settings'
Starting development server at http://10.10.23.14:9999/
Quit the server with CONTROL-C.
Performing system checks...

System check identified no issues (0 silenced).
March 26, 2018 - 03:16:04
Django version 2.0.3, using settings 'project.settings'
Starting development server at http://10.10.23.14:9999/
Quit the server with CONTROL-C.
[26/Mar/2018 03:55:52] "GET / HTTP/1.0" 200 8330
[26/Mar/2018 03:55:52] "GET /static/css/bootstrap.css HTTP/1.0" 304 0
[26/Mar/2018 03:55:52] "GET /static/js/jquery-1.10.2.min.js HTTP/1.0" 304 0
[26/Mar/2018 03:55:52] "GET /static/js/lucky.js HTTP/1.0" 304 0
[26/Mar/2018 03:55:52] "GET /static/js/bootstrap.min.js HTTP/1.0" 304 0
Not Found: /favicon.ico
[26/Mar/2018 03:55:53] "GET /favicon.ico HTTP/1.0" 404 2543
[26/Mar/2018 03:55:54] "GET / HTTP/1.0" 200 8330
[26/Mar/2018 03:55:55] "GET / HTTP/1.0" 200 8330
[26/Mar/2018 03:55:55] "GET / HTTP/1.0" 200 8330
[26/Mar/2018 03:55:55] "GET / HTTP/1.0" 200 8330
('INSERT INTO `mobile` (`mobile`, `uid`) VALUES (%s, %s)', ['15800022254', 22254])
('UPDATE `userbase` SET `mobile` = %s, `mobileareacode` = %s WHERE (`uid` = %s)', ['15800022254', '+86', 22254])
[26/Mar/2018 03:56:09] "POST /new_web/bd_sj HTTP/1.0" 200 82
Not Found: /favicon.ico
[26/Mar/2018 04:02:16] "GET /favicon.ico HTTP/1.0" 404 2543
Performing system checks...

System check identified no issues (0 silenced).
March 26, 2018 - 03:16:10
Django version 2.0.3, using settings 'project.settings'
Starting development server at http://10.10.23.14:9999/
Quit the server with CONTROL-C.
Performing system checks...

System check identified no issues (0 silenced).
March 26, 2018 - 05:02:51
Django version 2.0.3, using settings 'project.settings'
Starting development server at http://10.10.23.14:9999/
Quit the server with CONTROL-C.
Traceback (most recent call last):
  File "/home/lxy/share/django/project/manage.py", line 10, in <module>
    execute_from_command_line(sys.argv)
  File "/usr/local/python3/lib/python3.6/site-packages/django/core/management/__init__.py", line 371, in execute_from_command_line
    utility.execute()
  File "/usr/local/python3/lib/python3.6/site-packages/django/core/management/__init__.py", line 365, in execute
    self.fetch_command(subcommand).run_from_argv(self.argv)
  File "/usr/local/python3/lib/python3.6/site-packages/django/core/management/base.py", line 288, in run_from_argv
    self.execute(*args, **cmd_options)
  File "/usr/local/python3/lib/python3.6/site-packages/django/core/management/commands/runserver.py", line 61, in execute
    super().execute(*args, **options)
  File "/usr/local/python3/lib/python3.6/site-packages/django/core/management/base.py", line 335, in execute
    output = self.handle(*args, **options)
  File "/usr/local/python3/lib/python3.6/site-packages/django/core/management/commands/runserver.py", line 98, in handle
    self.run(**options)
  File "/usr/local/python3/lib/python3.6/site-packages/django/core/management/commands/runserver.py", line 105, in run
    autoreload.main(self.inner_run, None, options)
  File "/usr/local/python3/lib/python3.6/site-packages/django/utils/autoreload.py", line 317, in main
    python_reloader(wrapped_main_func, args, kwargs)
  File "/usr/local/python3/lib/python3.6/site-packages/django/utils/autoreload.py", line 296, in python_reloader
    reloader_thread()
  File "/usr/local/python3/lib/python3.6/site-packages/django/utils/autoreload.py", line 274, in reloader_thread
    change = fn()
  File "/usr/local/python3/lib/python3.6/site-packages/django/utils/autoreload.py", line 204, in code_changed
    stat = os.stat(filename)
FileNotFoundError: [Errno 2] No such file or directory: '/home/lxy/share/django/project/app/views.py'
[26/Mar/2018 05:03:18] "GET / HTTP/1.0" 200 8330
Not Found: /favicon.ico
[26/Mar/2018 05:03:19] "GET /favicon.ico HTTP/1.0" 404 2543
[26/Mar/2018 05:03:19] "GET / HTTP/1.0" 200 8330
[26/Mar/2018 05:03:19] "GET / HTTP/1.0" 200 8330
[26/Mar/2018 05:03:20] "GET / HTTP/1.0" 200 8330
[26/Mar/2018 05:03:20] "GET / HTTP/1.0" 200 8330
Internal Server Error: /new_web/zc
Traceback (most recent call last):
  File "/usr/local/python3/lib/python3.6/site-packages/django/core/handlers/exception.py", line 35, in inner
    response = get_response(request)
  File "/usr/local/python3/lib/python3.6/site-packages/django/core/handlers/base.py", line 128, in _get_response
    response = self.process_exception_by_middleware(e, request)
  File "/usr/local/python3/lib/python3.6/site-packages/django/core/handlers/base.py", line 126, in _get_response
    response = wrapped_callback(request, *callback_args, **callback_kwargs)
  File "/home/lxy/share/django/project/app/views.py", line 18, in new_web
    return eval(method)(request)
  File "<string>", line 1, in <module>
NameError: name 'zc' is not defined
[26/Mar/2018 05:03:23] "POST /new_web/zc HTTP/1.0" 500 14236
[26/Mar/2018 05:03:52] "GET / HTTP/1.0" 200 8330
[26/Mar/2018 05:03:52] "GET /static/css/bootstrap.css HTTP/1.0" 200 121220
[26/Mar/2018 05:03:52] "GET /static/js/jquery-1.10.2.min.js HTTP/1.0" 200 93107
[26/Mar/2018 05:03:52] "GET /static/js/bootstrap.min.js HTTP/1.0" 200 29110
[26/Mar/2018 05:03:52] "GET /static/js/lucky.js HTTP/1.0" 200 1795
Not Found: /favicon.ico
[26/Mar/2018 05:03:52] "GET /favicon.ico HTTP/1.0" 404 2543
[26/Mar/2018 05:03:52] "GET / HTTP/1.0" 200 8330
[26/Mar/2018 05:03:52] "GET /static/css/bootstrap.css HTTP/1.0" 200 121220
[26/Mar/2018 05:03:52] "GET /static/js/jquery-1.10.2.min.js HTTP/1.0" 200 93107
[26/Mar/2018 05:03:52] "GET /static/js/lucky.js HTTP/1.0" 200 1795
[26/Mar/2018 05:03:52] "GET /static/js/bootstrap.min.js HTTP/1.0" 200 29110
Not Found: /favicon.ico
[26/Mar/2018 05:03:53] "GET /favicon.ico HTTP/1.0" 404 2543
[26/Mar/2018 05:04:06] "GET / HTTP/1.0" 200 8330
[26/Mar/2018 05:04:06] "GET /static/css/bootstrap.css HTTP/1.0" 200 121220
[26/Mar/2018 05:04:06] "GET /static/js/bootstrap.min.js HTTP/1.0" 200 29110
[26/Mar/2018 05:04:06] "GET /static/js/jquery-1.10.2.min.js HTTP/1.0" 200 93107
[26/Mar/2018 05:04:06] "GET /static/js/lucky.js HTTP/1.0" 200 1795
Not Found: /favicon.ico
[26/Mar/2018 05:04:06] "GET /favicon.ico HTTP/1.0" 404 2543
('SELECT `t1`.`uid`, `t1`.`username` FROM `username` AS `t1` WHERE (`t1`.`username` = %s) LIMIT 1', ['asfas2323'])
('INSERT INTO `uid` () VALUES ()', [])
('INSERT INTO `userbase` (`email`, `mobile`, `mobileareacode`, `name`, `openid`, `uid`, `weixin`) VALUES (%s, %s, %s, %s, %s, %s, %s)', ['', '', '', 'asfas2323', '', 22261, ''])
('INSERT INTO `username` (`uid`, `username`) VALUES (%s, %s)', [22261, 'asfas2323'])
('INSERT INTO `userinfo` (`uid`, `img`, `lv`, `password`) VALUES (%s, %s, %s, %s)', [22261, '', 0, 'c4ca4238a0b923820dcc509a6f75849b'])
[26/Mar/2018 05:04:09] "POST /new_web/register HTTP/1.0" 200 95
Performing system checks...

System check identified no issues (0 silenced).
March 26, 2018 - 05:03:14
Django version 2.0.3, using settings 'project.settings'
Starting development server at http://10.10.23.14:9999/
Quit the server with CONTROL-C.
22261 25
{"nickname": "asfas2323nc", "password": "c4ca4238a0b923820dcc509a6f75849b", "img": "", "lv": 0, "regtime": 1522040649}
Performing system checks...

System check identified no issues (0 silenced).
March 26, 2018 - 05:07:00
Django version 2.0.3, using settings 'project.settings'
Starting development server at http://10.10.23.14:9999/
Quit the server with CONTROL-C.
Performing system checks...

System check identified no issues (0 silenced).
March 26, 2018 - 05:11:23
Django version 2.0.3, using settings 'project.settings'
Starting development server at http://10.10.23.14:9999/
Quit the server with CONTROL-C.
Unhandled exception in thread started by <function check_errors.<locals>.wrapper at 0x7f5138a679d8>
Traceback (most recent call last):
  File "/usr/local/python3/lib/python3.6/site-packages/django/utils/autoreload.py", line 225, in wrapper
    fn(*args, **kwargs)
  File "/usr/local/python3/lib/python3.6/site-packages/django/core/management/commands/runserver.py", line 120, in inner_run
    self.check(display_num_errors=True)
  File "/usr/local/python3/lib/python3.6/site-packages/django/core/management/base.py", line 364, in check
    include_deployment_checks=include_deployment_checks,
  File "/usr/local/python3/lib/python3.6/site-packages/django/core/management/base.py", line 351, in _run_checks
    return checks.run_checks(**kwargs)
  File "/usr/local/python3/lib/python3.6/site-packages/django/core/checks/registry.py", line 73, in run_checks
    new_errors = check(app_configs=app_configs)
  File "/usr/local/python3/lib/python3.6/site-packages/django/core/checks/urls.py", line 13, in check_url_config
    return check_resolver(resolver)
  File "/usr/local/python3/lib/python3.6/site-packages/django/core/checks/urls.py", line 23, in check_resolver
    return check_method()
  File "/usr/local/python3/lib/python3.6/site-packages/django/urls/resolvers.py", line 397, in check
    for pattern in self.url_patterns:
  File "/usr/local/python3/lib/python3.6/site-packages/django/utils/functional.py", line 36, in __get__
    res = instance.__dict__[self.name] = self.func(instance)
  File "/usr/local/python3/lib/python3.6/site-packages/django/urls/resolvers.py", line 536, in url_patterns
    patterns = getattr(self.urlconf_module, "urlpatterns", self.urlconf_module)
  File "/usr/local/python3/lib/python3.6/site-packages/django/utils/functional.py", line 36, in __get__
    res = instance.__dict__[self.name] = self.func(instance)
  File "/usr/local/python3/lib/python3.6/site-packages/django/urls/resolvers.py", line 529, in urlconf_module
    return import_module(self.urlconf_name)
  File "/usr/local/python3/lib/python3.6/importlib/__init__.py", line 126, in import_module
    return _bootstrap._gcd_import(name[level:], package, level)
  File "<frozen importlib._bootstrap>", line 994, in _gcd_import
  File "<frozen importlib._bootstrap>", line 971, in _find_and_load
  File "<frozen importlib._bootstrap>", line 955, in _find_and_load_unlocked
  File "<frozen importlib._bootstrap>", line 665, in _load_unlocked
  File "<frozen importlib._bootstrap_external>", line 678, in exec_module
  File "<frozen importlib._bootstrap>", line 219, in _call_with_frames_removed
  File "/home/lxy/share/django/project/project/urls.py", line 18, in <module>
    from app import views as app_views
  File "/home/lxy/share/django/project/app/views.py", line 5, in <module>
    from common.common import Common
  File "/home/lxy/share/common/common.py", line 284
    for key,value in data.items()
                                ^
SyntaxError: invalid syntax
Performing system checks...

Unhandled exception in thread started by <function check_errors.<locals>.wrapper at 0x7f75eb56f9d8>
Traceback (most recent call last):
  File "/usr/local/python3/lib/python3.6/site-packages/django/utils/autoreload.py", line 225, in wrapper
    fn(*args, **kwargs)
  File "/usr/local/python3/lib/python3.6/site-packages/django/core/management/commands/runserver.py", line 120, in inner_run
    self.check(display_num_errors=True)
  File "/usr/local/python3/lib/python3.6/site-packages/django/core/management/base.py", line 364, in check
    include_deployment_checks=include_deployment_checks,
  File "/usr/local/python3/lib/python3.6/site-packages/django/core/management/base.py", line 351, in _run_checks
    return checks.run_checks(**kwargs)
  File "/usr/local/python3/lib/python3.6/site-packages/django/core/checks/registry.py", line 73, in run_checks
    new_errors = check(app_configs=app_configs)
  File "/usr/local/python3/lib/python3.6/site-packages/django/core/checks/urls.py", line 13, in check_url_config
    return check_resolver(resolver)
  File "/usr/local/python3/lib/python3.6/site-packages/django/core/checks/urls.py", line 23, in check_resolver
    return check_method()
  File "/usr/local/python3/lib/python3.6/site-packages/django/urls/resolvers.py", line 397, in check
    for pattern in self.url_patterns:
  File "/usr/local/python3/lib/python3.6/site-packages/django/utils/functional.py", line 36, in __get__
    res = instance.__dict__[self.name] = self.func(instance)
  File "/usr/local/python3/lib/python3.6/site-packages/django/urls/resolvers.py", line 536, in url_patterns
    patterns = getattr(self.urlconf_module, "urlpatterns", self.urlconf_module)
  File "/usr/local/python3/lib/python3.6/site-packages/django/utils/functional.py", line 36, in __get__
    res = instance.__dict__[self.name] = self.func(instance)
  File "/usr/local/python3/lib/python3.6/site-packages/django/urls/resolvers.py", line 529, in urlconf_module
    return import_module(self.urlconf_name)
  File "/usr/local/python3/lib/python3.6/importlib/__init__.py", line 126, in import_module
    return _bootstrap._gcd_import(name[level:], package, level)
  File "<frozen importlib._bootstrap>", line 994, in _gcd_import
  File "<frozen importlib._bootstrap>", line 971, in _find_and_load
  File "<frozen importlib._bootstrap>", line 955, in _find_and_load_unlocked
  File "<frozen importlib._bootstrap>", line 665, in _load_unlocked
  File "<frozen importlib._bootstrap_external>", line 678, in exec_module
  File "<frozen importlib._bootstrap>", line 219, in _call_with_frames_removed
  File "/home/lxy/share/django/project/project/urls.py", line 18, in <module>
    from app import views as app_views
  File "/home/lxy/share/django/project/app/views.py", line 5, in <module>
    from common.common import Common
  File "/home/lxy/share/common/common.py", line 287
    Common.REDIS_INST.hmset('hm_userbaseinfo_{}'.format(uid),data)
         ^
IndentationError: expected an indented block
Performing system checks...

Performing system checks...

System check identified no issues (0 silenced).
March 26, 2018 - 05:12:10
Django version 2.0.3, using settings 'project.settings'
Starting development server at http://10.10.23.14:9999/
Quit the server with CONTROL-C.
Performing system checks...

System check identified no issues (0 silenced).
March 26, 2018 - 05:13:15
Django version 2.0.3, using settings 'project.settings'
Starting development server at http://10.10.23.14:9999/
Quit the server with CONTROL-C.
Performing system checks...

System check identified no issues (0 silenced).
March 26, 2018 - 05:14:10
Django version 2.0.3, using settings 'project.settings'
Starting development server at http://10.10.23.14:9999/
Quit the server with CONTROL-C.
('SELECT `t1`.`uid`, `t1`.`username` FROM `username` AS `t1` WHERE (`t1`.`username` = %s) LIMIT 1', ['asfas23231'])
('INSERT INTO `uid` () VALUES ()', [])
('INSERT INTO `userbase` (`email`, `mobile`, `mobileareacode`, `name`, `openid`, `uid`, `weixin`) VALUES (%s, %s, %s, %s, %s, %s, %s)', ['', '', '', 'asfas23231', '', 22264, ''])
('INSERT INTO `username` (`uid`, `username`) VALUES (%s, %s)', [22264, 'asfas23231'])
('INSERT INTO `userinfo` (`uid`, `img`, `lv`, `password`) VALUES (%s, %s, %s, %s)', [22264, '', 0, 'c4ca4238a0b923820dcc509a6f75849b'])
[26/Mar/2018 05:14:42] "POST /new_web/register HTTP/1.0" 200 95
('SELECT `t1`.`uid` FROM `userbase` AS `t1` WHERE (`t1`.`name` = %s) LIMIT 1', ['asfas23231'])
[26/Mar/2018 05:15:08] "POST /new_web/find_uid HTTP/1.0" 200 43
('INSERT INTO `mobile` (`mobile`, `uid`) VALUES (%s, %s)', ['15800022264', 22264])
('UPDATE `userbase` SET `mobile` = %s, `mobileareacode` = %s WHERE (`uid` = %s)', ['15800022264', '+86', 22264])
[26/Mar/2018 05:15:12] "POST /new_web/bd_sj HTTP/1.0" 200 82
('SELECT `t1`.`id`, `t1`.`bean`, `t1`.`coin`, `t1`.`ts`, `t1`.`uid` FROM `money` AS `t1` WHERE (`t1`.`uid` = %s) LIMIT 1', [22264])
('INSERT INTO `money` (`bean`, `coin`, `ts`, `uid`) VALUES (%s, %s, %s, %s)', ['235235', '325235', 1522041259, 22264])
[26/Mar/2018 05:15:29] "POST /new_web/set_money HTTP/1.0" 200 23
